<?xml version="1.0"?>
<robot name="physics">
    <link name="slideBar">
        <visual>
            <geometry>
                <cylinder radius="0.02" length="2"/>
            </geometry>
            <origin rpy="0 1.5708 0" xyz="0 0 0"/>
            <material name="green">
                <color rgba="0 0.8 .8 1"/>
            </material>
        </visual>
        <inertial>
            <mass value="1"/>
            <inertia ixx="1.0" ixy="0.0" ixz="0.0" iyy="1.0" iyz="0.0" izz="1.0"/>
        </inertial>
    </link>
    <link name="base">
        <visual>
            <geometry>
                <cylinder radius="0.1" length="0.2"/>
            </geometry>
            <origin rpy="0 1.5708 0" xyz="0 0 0"/>
            <material name="blue">
                <color rgba="0 0 .8 1"/>
            </material>
        </visual>
        <collision>
            <geometry>
                <cylinder radius="0.1" length="0.2"/>
            </geometry>
            <origin xyz="0 0 0"/>
        </collision>
        <inertial>
            <mass value="10"/>
            <inertia ixx="1.0" ixy="0.0" ixz="0.0" iyy="1.0" iyz="0.0" izz="1.0"/>
        </inertial>
    </link>
    <joint name="slider_to_base" type="prismatic">
        <axis xyz="1 0 0"/>
        <origin xyz="0.0 0.0 0.0"/>
        <parent link="slideBar"/>
        <child link="base"/>
        <limit effort="3.0" lower="-1"  per="1" velocity="1000"/>
        <!-- <dynamics damping="0.0"/> -->
    </joint>
    <link name="pendulum">
        <visual>
            <geometry>
                <cylinder radius="0.05" length="0.6"/>
            </geometry>
            <origin xyz="0 0 0.3"/>
            <material name="white">
                <color rgba="1 1 1 1"/>
            </material>
        </visual>
        <inertial>
            <origin xyz="0 0 0.3"/>
            <mass value="50.0"/>
            <inertia ixx="1.0" ixy="0.0" ixz="0.0" iyy="1.0" iyz="0.0" izz="1.0"/>
        </inertial>
        <collision>
            <geometry>
                <cylinder radius="0.05" length="0.6"/>
            </geometry>
            <origin rpy="0 0 0" xyz="0 0 0.3"/>
        </collision>
    </link>
    <joint name="base_to_pendulum" type="continuous">
        <axis xyz="0 1 0"/>
        <origin xyz="0.0 0.0 0"/>
        <parent link="base"/>
        <child link="pendulum"/>
        <!-- <limit effort="3.0" lower="-1.5709" upper="1.5709" velocity="1000"/> -->
    </joint>
</robot>